Workbook

Sheet Datos_Ejemplo.csv
A1: PacienteID | B1: NombreCompleto | C1: FechaNacimiento | D1: Edad | E1: Genero | F1: Diagnostico | G1: FechaIngreso | H1: FechaAlta | I1: DiasHospitalizado | J1: SeguroMedico | K1: CostoEstimado_USD
A2: 1 | B2: Luisa HernÃ¡ndez | C2: 27395 | D2: 51 | E2: F | F2: COVID-19 | G2: 45634 | H2: 45712 | I2: 5 | K2: 16301.13
A3: 2 | B3: Pedro LÃ³pez | C3: 12419 | D3: 92 | E3: M | F3: NeumonÃ­a | G3: 45585 | H3: 45504 | I3: 18 | K3: 19622.52
A4: 3 | B4: Miguel MartÃ­nez | C4: 40909 | D4: 14 | E4: F | F4: Asma | G4: 45164 | H4: 45307 | I4: 5 | J4: Publico | K4: 13169.22
A5: 4 | B5: Ana PÃ©rez | C5: 20090 | D5: 71 | E5: M | F5: Diabetes | G5: 44939 | H5: 44948 | I5: 2 | J5: Publico | K5: 12458.69
A6: 5 | B6: Jorge SÃ¡nchez | C6: 24107 | D6: 60 | E6: M | G6: 45183 | H6: 45806 | I6: 18 | J6: N/A | K6: 6320.56
A7: 6 | B7: Juan MartÃ­nez | C7: 38717 | D7: 20 | E7: M | F7: Diabetes | G7: 45440 | H7: 45104 | I7: 24 | J7: Privado | K7: 310.31
A8: 7 | B8: Laura HernÃ¡ndez | D8: 82 | E8: M | G8: 45136 | H8: 45290 | I8: 35 | J8: Publico | K8: 3755.14
A9: 8 | B9: JosÃ© MartÃ­nez | C9: 14611 | D9: 86 | E9: F | F9: Asma | G9: 45410 | H9: 44949 | I9: 2 | J9: Publico | K9: 11647.05
A10: 9 | B10: Carlos MartÃ­nez | C10: 18994 | D10: 74 | E10: F | F10: NeumonÃ­a | G10: 45291 | H10: 45764 | I10: 18 | J10: N/A | K10: 2941.46
A11: 10 | B11: Jorge SÃ¡nchez | C11: 18994 | D11: 74 | E11: M | F11: NeumonÃ­a | G11: 45151 | H11: 45475 | I11: 5 | J11: Privado | K11: 17665.1
A12: 11 | B12: Ricardo GÃ³mez | C12: 14246 | D12: 87 | E12: F | F12: Diabetes | G12: 45120 | H12: 45177 | I12: 19 | J12: Privado | K12: 3681.71
A13: 12 | B13: JosÃ© Cruz | C13: 37622 | D13: 23 | E13: F | F13: NeumonÃ­a | G13: 45122 | H13: 45588 | I13: 15 | J13: Publico | K13: 10394.3
A14: 13 | B14: Pedro SÃ¡nchez | C14: 45292 | D14: 2 | E14: M | F14: Gripe | G14: 45326 | H14: 45000 | I14: 1 | J14: Privado | K14: 10191.47
A15: 14 | B15: Pedro RamÃ­rez | C15: 38352 | D15: 21 | E15: M | F15: Gripe | G15: 44983 | H15: 45018 | I15: 1 | J15: Privado | K15: 12039.31
A16: 15 | B16: Pedro HernÃ¡ndez | C16: 27029 | D16: 52 | G16: 45551 | H16: 45103 | I16: 34 | J16: Privado | K16: 6481.42
A17: 16 | B17: MarÃ­a GÃ³mez | C17: 45657 | D17: 1 | E17: F | F17: Asma | G17: 45139 | H17: 45053 | I17: 12 | K17: 17458.04
A18: 17 | B18: Pedro PÃ©rez | C18: 14246 | D18: 87 | F18: COVID-19 | G18: 45205 | H18: 45131 | I18: 35 | J18: Privado | K18: 8830.46
A19: 18 | B19: JosÃ© HernÃ¡ndez | C19: 35430 | D19: 29 | E19: M | F19: Gripe | G19: 45306 | H19: 45173 | I19: 24 | K19: 13973.09
A20: 19 | B20: Carmen LÃ³pez | C20: 32508 | D20: 37 | E20: F | G20: 45043 | H20: 45538 | I20: 18 | J20: Privado | K20: 12681.81
A21: 20 | B21: Jorge Morales | C21: 45657 | D21: 1 | E21: M | F21: NeumonÃ­a | G21: 45377 | H21: 45198 | I21: 1 | J21: Privado | K21: 2254.84
A22: 21 | B22: Carlos RodrÃ­guez | C22: 23012 | D22: 63 | E22: M | F22: Asma | G22: 45525 | H22: 44971 | I22: 8 | J22: Privado | K22: 12415.05
A23: 22 | B23: Laura PÃ©rez | C23: 24473 | D23: 59 | E23: F | G23: 45336 | H23: 45661 | I23: 16 | J23: Publico | K23: 10969.12
A24: 23 | B24: Carlos LÃ³pez | C24: 38717 | D24: 20 | E24: M | G24: 45293 | H24: 45536 | I24: 16 | J24: Publico | K24: 17961.94
A25: 24 | B25: Carmen MartÃ­nez | C25: 34334 | D25: 32 | E25: M | F25: Gripe | G25: 45039 | H25: 45475 | I25: 24 | K25: 17605.62
A26: 25 | B26: Carlos HernÃ¡ndez | C26: 18629 | D26: 75 | E26: M | F26: HipertensiÃ³n | G26: 45090 | H26: 45095 | I26: 37 | J26: Privado | K26: 2934.19
A27: 26 | B27: Carmen MartÃ­nez | C27: 25203 | D27: 57 | E27: M | F27: Asma | G27: 44930 | H27: 45362 | I27: 39 | K27: 1541.87
A28: 27 | B28: Carlos HernÃ¡ndez | C28: 38352 | D28: 21 | E28: F | F28: Diabetes | G28: 45556 | H28: 44957 | I28: 25 | J28: Privado | K28: 5821.3
A29: 28 | B29: JosÃ© SÃ¡nchez | C29: 13880 | D29: 88 | E29: F | G29: 44949 | H29: 45721 | I29: 2 | J29: N/A | K29: 19730.92
A30: 29 | B30: MarÃ­a PÃ©rez | D30: 48 | E30: M | F30: Gripe | G30: 45528 | H30: 45524 | I30: 22 | K30: 333.63
A31: 30 | B31: Ana RamÃ­rez | C31: 13150 | D31: 90 | E31: M | F31: Diabetes | G31: 45018 | H31: 45284 | I31: 0 | J31: Publico | K31: 13425.13
A32: 31 | B32: Laura Morales | C32: 24838 | D32: 58 | E32: M | F32: Asma | G32: 45395 | H32: 45418 | I32: 23 | J32: N/A | K32: 12131.13
A33: 32 | B33: Carlos RodrÃ­guez | C33: 31047 | D33: 41 | E33: F | F33: Gripe | G33: 45081 | H33: 45560 | I33: 7 | J33: Publico | K33: 12896.22
A34: 33 | B34: Luis MartÃ­nez | C34: 12785 | D34: 91 | E34: M | F34: Diabetes | G34: 45553 | H34: 45726 | I34: 21 | J34: N/A | K34: 4287.55
A35: 34 | B35: Elena Morales | C35: 24473 | D35: 59 | E35: F | F35: COVID-19 | G35: 45133 | H35: 45175 | I35: 26 | J35: N/A | K35: 4457.02
A36: 35 | B36: Carlos Cruz | C36: 17168 | D36: 79 | E36: M | G36: 45007 | H36: 45623 | I36: 4 | J36: N/A | K36: 8555.91
A37: 36 | B37: Ana RodrÃ­guez | C37: 40909 | D37: 14 | E37: M | F37: COVID-19 | G37: 45541 | H37: 45180 | I37: 20 | K37: 1826.74
A38: 37 | B38: Carmen GÃ³mez | C38: 23742 | D38: 61 | E38: F | F38: HipertensiÃ³n | G38: 45409 | H38: 45712 | I38: 24 | K38: 1399.73
A39: 38 | B39: Miguel Cruz | C39: 23742 | D39: 61 | E39: F | F39: NeumonÃ­a | G39: 45518 | H39: 45648 | I39: 39 | J39: Publico | K39: 1676.03
A40: 39 | B40: Ana RodrÃ­guez | C40: 29221 | D40: 46 | E40: M | F40: Asma | G40: 45333 | H40: 45793 | I40: 6 | K40: 11416.88
...

Sheet Errores
B2: Errores encontrados
A5: Columna | B5: Tipo de error | C5: Acción sugerida
A6: FechaNacimiento | B6: Valores faltantes | C6: Revisar o calcular con Edad
A7: Edad | B7: Valores faltantes | C7: Calcular desde FechaNacimiento
A8: Genero | B8: Valores faltantes | C8: Marcar como No especificado
A9: Diagnostico | B9: Valores faltantes | C9: Marcar como No registrado
A10: SeguroMedico | B10: Valores faltantes | C10: Marcar como N/A
A11: FechaAlta / FechaIngreso | B11: FechaAlta antes de FechaIngreso | C11: Revisar inconsistencia
A12: DiasHospitalizado | B12: No coincide con diferencia entre fechas | C12: Recalcular con fechas
A13: PacienteID | B13: Duplicados | C13: Sin acción
A14: Filas completas | B14: Duplicados | C14: Sin acción
A15: Edad / FechaNacimiento | B15: Edad extrema o fecha estimada inválida | C15: Revisar, no corregir sin fuente confiable
A16: NombreCompleto / Diagnostico | B16: Texto mal codificado | C16: Revisar tildes y caracteres especiales
A17: CostoEstimado_USD | B17: Formato de dato inconsistente | C17: Aplicar formato moneda USD y verificar que sea numérico

Sheet Correcciones
C2: Correcciones
A5: Columna | B5: Tipo de corrección | C5: Valor original | D5: Valor corregido | E5: Motivo
A6: Edad | B6: Imputación | C6: Vacío | D6: Calculado con DATEDIF | E6: Se calculó desde FechaNacimiento
A7: Genero | B7: Relleno | C7: Vacío | D7: No especificado | E7: No había información
A8: Diagnostico | B8: Relleno | C8: Vacío | D8: No registrado | E8: Dato médico faltante
A9: SeguroMedico | B9: Relleno | C9: Vacío | D9: N/A | E9: No aplica o no registrado
A10: FechaAlta | B10: Corrección lógica | C10: FechaAlta antes de FechaIngreso | D10: FechaIngreso + DiasHospitalizado | E10: Se recalculó la fecha de alta usando la duración hospitalaria registrada
A11: DiasHospitalizado | B11: Recalculado | C11: Valores negativos/incoherentes | D11: Valor absoluto de los días hospitalizados | | E11: Se corrigieron valores negativos para mantener una duración válida
A12: FechaNacimiento | B12: Imputación aproximada | C12: Vacío | D12: Estimada con Edad | E12: Se usó 1/1 del año estimado porque no había fecha exacta
A13: NombreCompleto | B13: Corrección de codificación | C13: Caracteres extraños (ej: RamÃ­rez) | D13: Pendiente o corregido parcialmente | E13: Problema de acentos/tildes por codificación CSV
A14: Diagnostico | B14: Corrección de codificación | C14: Caracteres extraños (ej: NeumonÃ­a) | D14: Pendiente o corregido parcialmente | E14: Problema de acentos/tildes por codificación CSV
A15: CostoEstimado_USD | B15: Formato de dato | C15: Número sin formato de moneda | D15: Formato Currency USD | E15: Se estandarizó como moneda
A16: Filas completas | B16: Verificación | C16: Sin duplicados | D16: No aplica | E16: No se encontraron registros duplicados

Sheet Datos_Corregidos
A1: PacienteID | B1: NombreCompleto | C1: FechaNacimiento | D1: Edad | E1: Genero | F1: Diagnostico | G1: FechaIngreso | H1: FechaAlta | I1: DiasHospitalizado | J1: SeguroMedico | K1: CostoEstimado_USD | L1: ValidacionFechas | M1: DiasOriginal | N1: DiasNuevo | O1: FechaAltaNueva
A2: 1 | B2: Luisa Hernández | C2: 27395 | D2: 51 | E2: F | F2: COVID-19 | G2: 45634 | H2: =TablaDatos[[#This Row],[FechaIngreso]]+TablaDatos[[#This Row],[DiasNuevo]] -> 45639 | I2: 5 | J2: N/A | K2: 16301.13 | L2: =TablaDatos[[#This Row],[FechaAlta]] < TablaDatos[[#This Row],[FechaIngreso]] -> FALSE | M2: =_xlfn.XLOOKUP(TablaDatos[[#This Row],[PacienteID]],'Datos_Ejemplo.csv'!A:A,'Datos_Ejemplo.csv'!I:I) -> 5 | N2: =ABS(TablaDatos[[#This Row],[DiasOriginal]]) -> 5 | O2: =TablaDatos[[#This Row],[FechaIngreso]]+TablaDatos[[#This Row],[DiasNuevo]] -> 45639
A3: 2 | B3: Pedro López | C3: 12419 | D3: 92 | E3: M | F3: Neumonía | G3: 45585 | H3: =TablaDatos[[#This Row],[FechaIngreso]]+TablaDatos[[#This Row],[DiasNuevo]] -> 45603 | I3: 18 | J3: N/A | K3: 19622.52 | L3: =TablaDatos[[#This Row],[FechaAlta]] < TablaDatos[[#This Row],[FechaIngreso]] -> FALSE | M3: =_xlfn.XLOOKUP(TablaDatos[[#This Row],[PacienteID]],'Datos_Ejemplo.csv'!A:A,'Datos_Ejemplo.csv'!I:I) -> 18 | N3: =ABS(TablaDatos[[#This Row],[DiasOriginal]]) -> 18 | O3: =TablaDatos[[#This Row],[FechaIngreso]]+TablaDatos[[#This Row],[DiasNuevo]] -> 45603
A4: 3 | B4: Miguel Martínez | C4: 40909 | D4: 14 | E4: F | F4: Asma | G4: 45164 | H4: =TablaDatos[[#This Row],[FechaIngreso]]+TablaDatos[[#This Row],[DiasNuevo]] -> 45169 | I4: 5 | J4: Publico | K4: 13169.22 | L4: =TablaDatos[[#This Row],[FechaAlta]] < TablaDatos[[#This Row],[FechaIngreso]] -> FALSE | M4: =_xlfn.XLOOKUP(TablaDatos[[#This Row],[PacienteID]],'Datos_Ejemplo.csv'!A:A,'Datos_Ejemplo.csv'!I:I) -> 5 | N4: =ABS(TablaDatos[[#This Row],[DiasOriginal]]) -> 5 | O4: =TablaDatos[[#This Row],[FechaIngreso]]+TablaDatos[[#This Row],[DiasNuevo]] -> 45169
A5: 4 | B5: Ana Pérez | C5: 20090 | D5: 71 | E5: M | F5: Diabetes | G5: 44939 | H5: =TablaDatos[[#This Row],[FechaIngreso]]+TablaDatos[[#This Row],[DiasNuevo]] -> 44941 | I5: 2 | J5: Publico | K5: 12458.69 | L5: =TablaDatos[[#This Row],[FechaAlta]] < TablaDatos[[#This Row],[FechaIngreso]] -> FALSE | M5: =_xlfn.XLOOKUP(TablaDatos[[#This Row],[PacienteID]],'Datos_Ejemplo.csv'!A:A,'Datos_Ejemplo.csv'!I:I) -> 2 | N5: =ABS(TablaDatos[[#This Row],[DiasOriginal]]) -> 2 | O5: =TablaDatos[[#This Row],[FechaIngreso]]+TablaDatos[[#This Row],[DiasNuevo]] -> 44941
A6: 5 | B6: Jorge Sánchez | C6: 24107 | D6: 60 | E6: M | F6: No registrado | G6: 45183 | H6: =TablaDatos[[#This Row],[FechaIngreso]]+TablaDatos[[#This Row],[DiasNuevo]] -> 45201 | I6: 18 | J6: N/A | K6: 6320.56 | L6: =TablaDatos[[#This Row],[FechaAlta]] < TablaDatos[[#This Row],[FechaIngreso]] -> FALSE | M6: =_xlfn.XLOOKUP(TablaDatos[[#This Row],[PacienteID]],'Datos_Ejemplo.csv'!A:A,'Datos_Ejemplo.csv'!I:I) -> 18 | N6: =ABS(TablaDatos[[#This Row],[DiasOriginal]]) -> 18 | O6: =TablaDatos[[#This Row],[FechaIngreso]]+TablaDatos[[#This Row],[DiasNuevo]] -> 45201
A7: 6 | B7: Juan Martínez | C7: 38717 | D7: 20 | E7: M | F7: Diabetes | G7: 45440 | H7: =TablaDatos[[#This Row],[FechaIngreso]]+TablaDatos[[#This Row],[DiasNuevo]] -> 45464 | I7: 24 | J7: Privado | K7: 310.31 | L7: =TablaDatos[[#This Row],[FechaAlta]] < TablaDatos[[#This Row],[FechaIngreso]] -> FALSE | M7: =_xlfn.XLOOKUP(TablaDatos[[#This Row],[PacienteID]],'Datos_Ejemplo.csv'!A:A,'Datos_Ejemplo.csv'!I:I) -> 24 | N7: =ABS(TablaDatos[[#This Row],[DiasOriginal]]) -> 24 | O7: =TablaDatos[[#This Row],[FechaIngreso]]+TablaDatos[[#This Row],[DiasNuevo]] -> 45464
A8: 7 | B8: Laura Hernández | C8: =DATE(YEAR(TODAY())-TablaDatos[[#This Row],[Edad]],1,1) -> 16072 | D8: 82 | E8: M | F8: No registrado | G8: 45136 | H8: =TablaDatos[[#This Row],[FechaIngreso]]+TablaDatos[[#This Row],[DiasNuevo]] -> 45171 | I8: 35 | J8: Publico | K8: 3755.14 | L8: =TablaDatos[[#This Row],[FechaAlta]] < TablaDatos[[#This Row],[FechaIngreso]] -> FALSE | M8: =_xlfn.XLOOKUP(TablaDatos[[#This Row],[PacienteID]],'Datos_Ejemplo.csv'!A:A,'Datos_Ejemplo.csv'!I:I) -> 35 | N8: =ABS(TablaDatos[[#This Row],[DiasOriginal]]) -> 35 | O8: =TablaDatos[[#This Row],[FechaIngreso]]+TablaDatos[[#This Row],[DiasNuevo]] -> 45171
A9: 8 | B9: José Martínez | C9: 14611 | D9: 86 | E9: F | F9: Asma | G9: 45410 | H9: =TablaDatos[[#This Row],[FechaIngreso]]+TablaDatos[[#This Row],[DiasNuevo]] -> 45412 | I9: 2 | J9: Publico | K9: 11647.05 | L9: =TablaDatos[[#This Row],[FechaAlta]] < TablaDatos[[#This Row],[FechaIngreso]] -> FALSE | M9: =_xlfn.XLOOKUP(TablaDatos[[#This Row],[PacienteID]],'Datos_Ejemplo.csv'!A:A,'Datos_Ejemplo.csv'!I:I) -> 2 | N9: =ABS(TablaDatos[[#This Row],[DiasOriginal]]) -> 2 | O9: =TablaDatos[[#This Row],[FechaIngreso]]+TablaDatos[[#This Row],[DiasNuevo]] -> 45412
A10: 9 | B10: Carlos Martínez | C10: 18994 | D10: 74 | E10: F | F10: Neumonía | G10: 45291 | H10: =TablaDatos[[#This Row],[FechaIngreso]]+TablaDatos[[#This Row],[DiasNuevo]] -> 45309 | I10: 18 | J10: N/A | K10: 2941.46 | L10: =TablaDatos[[#This Row],[FechaAlta]] < TablaDatos[[#This Row],[FechaIngreso]] -> FALSE | M10: =_xlfn.XLOOKUP(TablaDatos[[#This Row],[PacienteID]],'Datos_Ejemplo.csv'!A:A,'Datos_Ejemplo.csv'!I:I) -> 18 | N10: =ABS(TablaDatos[[#This Row],[DiasOriginal]]) -> 18 | O10: =TablaDatos[[#This Row],[FechaIngreso]]+TablaDatos[[#This Row],[DiasNuevo]] -> 45309
A11: 10 | B11: Jorge Sánchez | C11: 18994 | D11: 74 | E11: M | F11: Neumonía | G11: 45151 | H11: =TablaDatos[[#This Row],[FechaIngreso]]+TablaDatos[[#This Row],[DiasNuevo]] -> 45156 | I11: 5 | J11: Privado | K11: 17665.1 | L11: =TablaDatos[[#This Row],[FechaAlta]] < TablaDatos[[#This Row],[FechaIngreso]] -> FALSE | M11: =_xlfn.XLOOKUP(TablaDatos[[#This Row],[PacienteID]],'Datos_Ejemplo.csv'!A:A,'Datos_Ejemplo.csv'!I:I) -> 5 | N11: =ABS(TablaDatos[[#This Row],[DiasOriginal]]) -> 5 | O11: =TablaDatos[[#This Row],[FechaIngreso]]+TablaDatos[[#This Row],[DiasNuevo]] -> 45156
A12: 11 | B12: Ricardo Gómez | C12: 14246 | D12: 87 | E12: F | F12: Diabetes | G12: 45120 | H12: =TablaDatos[[#This Row],[FechaIngreso]]+TablaDatos[[#This Row],[DiasNuevo]] -> 45139 | I12: 19 | J12: Privado | K12: 3681.71 | L12: =TablaDatos[[#This Row],[FechaAlta]] < TablaDatos[[#This Row],[FechaIngreso]] -> FALSE | M12: =_xlfn.XLOOKUP(TablaDatos[[#This Row],[PacienteID]],'Datos_Ejemplo.csv'!A:A,'Datos_Ejemplo.csv'!I:I) -> 19 | N12: =ABS(TablaDatos[[#This Row],[DiasOriginal]]) -> 19 | O12: =TablaDatos[[#This Row],[FechaIngreso]]+TablaDatos[[#This Row],[DiasNuevo]] -> 45139
A13: 12 | B13: José Cruz | C13: 37622 | D13: 23 | E13: F | F13: Neumonía | G13: 45122 | H13: =TablaDatos[[#This Row],[FechaIngreso]]+TablaDatos[[#This Row],[DiasNuevo]] -> 45137 | I13: 15 | J13: Publico | K13: 10394.3 | L13: =TablaDatos[[#This Row],[FechaAlta]] < TablaDatos[[#This Row],[FechaIngreso]] -> FALSE | M13: =_xlfn.XLOOKUP(TablaDatos[[#This Row],[PacienteID]],'Datos_Ejemplo.csv'!A:A,'Datos_Ejemplo.csv'!I:I) -> 15 | N13: =ABS(TablaDatos[[#This Row],[DiasOriginal]]) -> 15 | O13: =TablaDatos[[#This Row],[FechaIngreso]]+TablaDatos[[#This Row],[DiasNuevo]] -> 45137
A14: 13 | B14: Pedro Sánchez | C14: 45292 | D14: 2 | E14: M | F14: Gripe | G14: 45326 | H14: =TablaDatos[[#This Row],[FechaIngreso]]+TablaDatos[[#This Row],[DiasNuevo]] -> 45327 | I14: 1 | J14: Privado | K14: 10191.47 | L14: =TablaDatos[[#This Row],[FechaAlta]] < TablaDatos[[#This Row],[FechaIngreso]] -> FALSE | M14: =_xlfn.XLOOKUP(TablaDatos[[#This Row],[PacienteID]],'Datos_Ejemplo.csv'!A:A,'Datos_Ejemplo.csv'!I:I) -> 1 | N14: =ABS(TablaDatos[[#This Row],[DiasOriginal]]) -> 1 | O14: =TablaDatos[[#This Row],[FechaIngreso]]+TablaDatos[[#This Row],[DiasNuevo]] -> 45327
A15: 14 | B15: Pedro Ramírez | C15: 38352 | D15: 21 | E15: M | F15: Gripe | G15: 44983 | H15: =TablaDatos[[#This Row],[FechaIngreso]]+TablaDatos[[#This Row],[DiasNuevo]] -> 44984 | I15: 1 | J15: Privado | K15: 12039.31 | L15: =TablaDatos[[#This Row],[FechaAlta]] < TablaDatos[[#This Row],[FechaIngreso]] -> FALSE | M15: =_xlfn.XLOOKUP(TablaDatos[[#This Row],[PacienteID]],'Datos_Ejemplo.csv'!A:A,'Datos_Ejemplo.csv'!I:I) -> 1 | N15: =ABS(TablaDatos[[#This Row],[DiasOriginal]]) -> 1 | O15: =TablaDatos[[#This Row],[FechaIngreso]]+TablaDatos[[#This Row],[DiasNuevo]] -> 44984
A16: 15 | B16: Pedro Hernández | C16: 27029 | D16: 52 | E16: No especificado | F16: No registrado | G16: 45551 | H16: =TablaDatos[[#This Row],[FechaIngreso]]+TablaDatos[[#This Row],[DiasNuevo]] -> 45585 | I16: 34 | J16: Privado | K16: 6481.42 | L16: =TablaDatos[[#This Row],[FechaAlta]] < TablaDatos[[#This Row],[FechaIngreso]] -> FALSE | M16: =_xlfn.XLOOKUP(TablaDatos[[#This Row],[PacienteID]],'Datos_Ejemplo.csv'!A:A,'Datos_Ejemplo.csv'!I:I) -> 34 | N16: =ABS(TablaDatos[[#This Row],[DiasOriginal]]) -> 34 | O16: =TablaDatos[[#This Row],[FechaIngreso]]+TablaDatos[[#This Row],[DiasNuevo]] -> 45585
A17: 16 | B17: María Gómez | C17: 45657 | D17: 1 | E17: F | F17: Asma | G17: 45139 | H17: =TablaDatos[[#This Row],[FechaIngreso]]+TablaDatos[[#This Row],[DiasNuevo]] -> 45151 | I17: 12 | J17: N/A | K17: 17458.04 | L17: =TablaDatos[[#This Row],[FechaAlta]] < TablaDatos[[#This Row],[FechaIngreso]] -> FALSE | M17: =_xlfn.XLOOKUP(TablaDatos[[#This Row],[PacienteID]],'Datos_Ejemplo.csv'!A:A,'Datos_Ejemplo.csv'!I:I) -> 12 | N17: =ABS(TablaDatos[[#This Row],[DiasOriginal]]) -> 12 | O17: =TablaDatos[[#This Row],[FechaIngreso]]+TablaDatos[[#This Row],[DiasNuevo]] -> 45151
A18: 17 | B18: Pedro Pérez | C18: 14246 | D18: 87 | E18: No especificado | F18: COVID-19 | G18: 45205 | H18: =TablaDatos[[#This Row],[FechaIngreso]]+TablaDatos[[#This Row],[DiasNuevo]] -> 45240 | I18: 35 | J18: Privado | K18: 8830.46 | L18: =TablaDatos[[#This Row],[FechaAlta]] < TablaDatos[[#This Row],[FechaIngreso]] -> FALSE | M18: =_xlfn.XLOOKUP(TablaDatos[[#This Row],[PacienteID]],'Datos_Ejemplo.csv'!A:A,'Datos_Ejemplo.csv'!I:I) -> 35 | N18: =ABS(TablaDatos[[#This Row],[DiasOriginal]]) -> 35 | O18: =TablaDatos[[#This Row],[FechaIngreso]]+TablaDatos[[#This Row],[DiasNuevo]] -> 45240
A19: 18 | B19: José Hernández | C19: 35430 | D19: 29 | E19: M | F19: Gripe | G19: 45306 | H19: =TablaDatos[[#This Row],[FechaIngreso]]+TablaDatos[[#This Row],[DiasNuevo]] -> 45330 | I19: 24 | J19: N/A | K19: 13973.09 | L19: =TablaDatos[[#This Row],[FechaAlta]] < TablaDatos[[#This Row],[FechaIngreso]] -> FALSE | M19: =_xlfn.XLOOKUP(TablaDatos[[#This Row],[PacienteID]],'Datos_Ejemplo.csv'!A:A,'Datos_Ejemplo.csv'!I:I) -> 24 | N19: =ABS(TablaDatos[[#This Row],[DiasOriginal]]) -> 24 | O19: =TablaDatos[[#This Row],[FechaIngreso]]+TablaDatos[[#This Row],[DiasNuevo]] -> 45330
A20: 19 | B20: Carmen López | C20: 32508 | D20: 37 | E20: F | F20: No registrado | G20: 45043 | H20: =TablaDatos[[#This Row],[FechaIngreso]]+TablaDatos[[#This Row],[DiasNuevo]] -> 45061 | I20: 18 | J20: Privado | K20: 12681.81 | L20: =TablaDatos[[#This Row],[FechaAlta]] < TablaDatos[[#This Row],[FechaIngreso]] -> FALSE | M20: =_xlfn.XLOOKUP(TablaDatos[[#This Row],[PacienteID]],'Datos_Ejemplo.csv'!A:A,'Datos_Ejemplo.csv'!I:I) -> 18 | N20: =ABS(TablaDatos[[#This Row],[DiasOriginal]]) -> 18 | O20: =TablaDatos[[#This Row],[FechaIngreso]]+TablaDatos[[#This Row],[DiasNuevo]] -> 45061
... A29: 28 | B29: José Sánchez | C29: 13880 | D29: 88 | E29: F | F29: No registrado | G29: 44949 | H29: =TablaDatos[[#This Row],[FechaIngreso]]+TablaDatos[[#This Row],[DiasNuevo]] -> 44951 | I29: 2 | J29: N/A | K29: 19730.92 | L29: =TablaDatos[[#This Row],[FechaAlta]] < TablaDatos[[#This Row],[FechaIngreso]] -> FALSE | M29: =_xlfn.XLOOKUP(TablaDatos[[#This Row],[PacienteID]],'Datos_Ejemplo.csv'!A:A,'Datos_Ejemplo.csv'!I:I) -> 2 | N29: =ABS(TablaDatos[[#This Row],[DiasOriginal]]) -> 2 | O29: =TablaDatos[[#This Row],[FechaIngreso]]+TablaDatos[[#This Row],[DiasNuevo]] -> 44951
A30: 29 | B30: María Pérez | C30: =DATE(YEAR(TODAY())-TablaDatos[[#This Row],[Edad]],1,1) -> 28491 | D30: 48 | E30: M | F30: Gripe | G30: 45528 | H30: =TablaDatos[[#This Row],[FechaIngreso]]+TablaDatos[[#This Row],[DiasNuevo]] -> 45550 | I30: 22 | J30: N/A | K30: 333.63 | L30: =TablaDatos[[#This Row],[FechaAlta]] < TablaDatos[[#This Row],[FechaIngreso]] -> FALSE | M30: =_xlfn.XLOOKUP(TablaDatos[[#This Row],[PacienteID]],'Datos_Ejemplo.csv'!A:A,'Datos_Ejemplo.csv'!I:I) -> 22 | N30: =ABS(TablaDatos[[#This Row],[DiasOriginal]]) -> 22 | O30: =TablaDatos[[#This Row],[FechaIngreso]]+TablaDatos[[#This Row],[DiasNuevo]] -> 45550
A31: 30 | B31: Ana Ramírez | C31: 13150 | D31: 90 | E31: M | F31: Diabetes | G31: 45018 | H31: =TablaDatos[[#This Row],[FechaIngreso]]+TablaDatos[[#This Row],[DiasNuevo]] -> 45018 | I31: 0 | J31: Publico | K31: 13425.13 | L31: =TablaDatos[[#This Row],[FechaAlta]] < TablaDatos[[#This Row],[FechaIngreso]] -> FALSE | M31: =_xlfn.XLOOKUP(TablaDatos[[#This Row],[PacienteID]],'Datos_Ejemplo.csv'!A:A,'Datos_Ejemplo.csv'!I:I) -> 0 | N31: =ABS(TablaDatos[[#This Row],[DiasOriginal]]) -> 0 | O31: =TablaDatos[[#This Row],[FechaIngreso]]+TablaDatos[[#This Row],[DiasNuevo]] -> 45018
A32: 31 | B32: Laura Morales | C32: 24838 | D32: 58 | E32: M | F32: Asma | G32: 45395 | H32: =TablaDatos[[#This Row],[FechaIngreso]]+TablaDatos[[#This Row],[DiasNuevo]] -> 45418 | I32: 23 | J32: N/A | K32: 12131.13 | L32: =TablaDatos[[#This Row],[FechaAlta]] < TablaDatos[[#This Row],[FechaIngreso]] -> FALSE | M32: =_xlfn.XLOOKUP(TablaDatos[[#This Row],[PacienteID]],'Datos_Ejemplo.csv'!A:A,'Datos_Ejemplo.csv'!I:I) -> 23 | N32: =ABS(TablaDatos[[#This Row],[DiasOriginal]]) -> 23 | O32: =TablaDatos[[#This Row],[FechaIngreso]]+TablaDatos[[#This Row],[DiasNuevo]] -> 45418
A33: 32 | B33: Carlos Rodríguez | C33: 31047 | D33: 41 | E33: F | F33: Gripe | G33: 45081 | H33: =TablaDatos[[#This Row],[FechaIngreso]]+TablaDatos[[#This Row],[DiasNuevo]] -> 45088 | I33: 7 | J33: Publico | K33: 12896.22 | L33: =TablaDatos[[#This Row],[FechaAlta]] < TablaDatos[[#This Row],[FechaIngreso]] -> FALSE | M33: =_xlfn.XLOOKUP(TablaDatos[[#This Row],[PacienteID]],'Datos_Ejemplo.csv'!A:A,'Datos_Ejemplo.csv'!I:I) -> 7 | N33: =ABS(TablaDatos[[#This Row],[DiasOriginal]]) -> 7 | O33: =TablaDatos[[#This Row],[FechaIngreso]]+TablaDatos[[#This Row],[DiasNuevo]] -> 45088
A34: 33 | B34: Luis Martínez | C34: 12785 | D34: 91 | E34: M | F34: Diabetes | G34: 45553 | H34: =TablaDatos[[#This Row],[FechaIngreso]]+TablaDatos[[#This Row],[DiasNuevo]] -> 45574 | I34: 21 | J34: N/A | K34: 4287.55 | L34: =TablaDatos[[#This Row],[FechaAlta]] < TablaDatos[[#This Row],[FechaIngreso]] -> FALSE | M34: =_xlfn.XLOOKUP(TablaDatos[[#This Row],[PacienteID]],'Datos_Ejemplo.csv'!A:A,'Datos_Ejemplo.csv'!I:I) -> 21 | N34: =ABS(TablaDatos[[#This Row],[DiasOriginal]]) -> 21 | O34: =TablaDatos[[#This Row],[FechaIngreso]]+TablaDatos[[#This Row],[DiasNuevo]] -> 45574
A35: 34 | B35: Elena Morales | C35: 24473 | D35: 59 | E35: F | F35: COVID-19 | G35: 45133 | H35: =TablaDatos[[#This Row],[FechaIngreso]]+TablaDatos[[#This Row],[DiasNuevo]] -> 45159 | I35: 26 | J35: N/A | K35: 4457.02 | L35: =TablaDatos[[#This Row],[FechaAlta]] < TablaDatos[[#This Row],[FechaIngreso]] -> FALSE | M35: =_xlfn.XLOOKUP(TablaDatos[[#This Row],[PacienteID]],'Datos_Ejemplo.csv'!A:A,'Datos_Ejemplo.csv'!I:I) -> 26 | N35: =ABS(TablaDatos[[#This Row],[DiasOriginal]]) -> 26 | O35: =TablaDatos[[#This Row],[FechaIngreso]]+TablaDatos[[#This Row],[DiasNuevo]] -> 45159
A36: 35 | B36: Carlos Cruz | C36: 17168 | D36: 79 | E36: M | F36: No registrado | G36: 45007 | H36: =TablaDatos[[#This Row],[FechaIngreso]]+TablaDatos[[#This Row],[DiasNuevo]] -> 45011 | I36: 4 | J36: N/A | K36: 8555.91 | L36: =TablaDatos[[#This Row],[FechaAlta]] < TablaDatos[[#This Row],[FechaIngreso]] -> FALSE | M36: =_xlfn.XLOOKUP(TablaDatos[[#This Row],[PacienteID]],'Datos_Ejemplo.csv'!A:A,'Datos_Ejemplo.csv'!I:I) -> 4 | N36: =ABS(TablaDatos[[#This Row],[DiasOriginal]]) -> 4 | O36: =TablaDatos[[#This Row],[FechaIngreso]]+TablaDatos[[#This Row],[DiasNuevo]] -> 45011
A37: 36 | B37: Ana Rodríguez | C37: 40909 | D37: 14 | E37: M | F37: COVID-19 | G37: 45541 | H37: =TablaDatos[[#This Row],[FechaIngreso]]+TablaDatos[[#This Row],[DiasNuevo]] -> 45561 | I37: 20 | J37: N/A | K37: 1826.74 | L37: =TablaDatos[[#This Row],[FechaAlta]] < TablaDatos[[#This Row],[FechaIngreso]] -> FALSE | M37: =_xlfn.XLOOKUP(TablaDatos[[#This Row],[PacienteID]],'Datos_Ejemplo.csv'!A:A,'Datos_Ejemplo.csv'!I:I) -> 20 | N37: =ABS(TablaDatos[[#This Row],[DiasOriginal]]) -> 20 | O37: =TablaDatos[[#This Row],[FechaIngreso]]+TablaDatos[[#This Row],[DiasNuevo]] -> 45561
A38: 37 | B38: Carmen Gómez | C38: 23742 | D38: 61 | E38: F | F38: Hipertensión | G38: 45409 | H38: =TablaDatos[[#This Row],[FechaIngreso]]+TablaDatos[[#This Row],[DiasNuevo]] -> 45433 | I38: 24 | J38: N/A | K38: 1399.73 | L38: =TablaDatos[[#This Row],[FechaAlta]] < TablaDatos[[#This Row],[FechaIngreso]] -> FALSE | M38: =_xlfn.XLOOKUP(TablaDatos[[#This Row],[PacienteID]],'Datos_Ejemplo.csv'!A:A,'Datos_Ejemplo.csv'!I:I) -> 24 | N38: =ABS(TablaDatos[[#This Row],[DiasOriginal]]) -> 24 | O38: =TablaDatos[[#This Row],[FechaIngreso]]+TablaDatos[[#This Row],[DiasNuevo]] -> 45433
A39: 38 | B39: Miguel Cruz | C39: 23742 | D39: 61 | E39: F | F39: Neumonía | G39: 45518 | H39: =TablaDatos[[#This Row],[FechaIngreso]]+TablaDatos[[#This Row],[DiasNuevo]] -> 45557 | I39: 39 | J39: Publico | K39: 1676.03 | L39: =TablaDatos[[#This Row],[FechaAlta]] < TablaDatos[[#This Row],[FechaIngreso]] -> FALSE | M39: =_xlfn.XLOOKUP(TablaDatos[[#This Row],[PacienteID]],'Datos_Ejemplo.csv'!A:A,'Datos_Ejemplo.csv'!I:I) -> 39 | N39: =ABS(TablaDatos[[#This Row],[DiasOriginal]]) -> 39 | O39: =TablaDatos[[#This Row],[FechaIngreso]]+TablaDatos[[#This Row],[DiasNuevo]] -> 45557
A40: 39 | B40: Ana Rodríguez | C40: 29221 | D40: 46 | E40: M | F40: Asma | G40: 45333 | H40: =TablaDatos[[#This Row],[FechaIngreso]]+TablaDatos[[#This Row],[DiasNuevo]] -> 45339 | I40: 6 | J40: N/A | K40: 11416.88 | L40: =TablaDatos[[#This Row],[FechaAlta]] < TablaDatos[[#This Row],[FechaIngreso]] -> FALSE | M40: =_xlfn.XLOOKUP(TablaDatos[[#This Row],[PacienteID]],'Datos_Ejemplo.csv'!A:A,'Datos_Ejemplo.csv'!I:I) -> 6 | N40: =ABS(TablaDatos[[#This Row],[DiasOriginal]]) -> 6 | O40: =TablaDatos[[#This Row],[FechaIngreso]]+TablaDatos[[#This Row],[DiasNuevo]] -> 45339
A41: 40 | B41: Luisa Sánchez | C41: 23742 | D41: =DATEDIF(TablaDatos[[#This Row],[FechaNacimiento]],TODAY(),"Y") -> 61 | E41: F | F41: Neumonía | G41: 45029 | H41: =TablaDatos[[#This Row],[FechaIngreso]]+TablaDatos[[#This Row],[DiasNuevo]] -> 45029 | I41: 0 | J41: Publico | K41: 7894.61 | L41: =TablaDatos[[#This Row],[FechaAlta]] < TablaDatos[[#This Row],[FechaIngreso]] -> FALSE | M41: =_xlfn.XLOOKUP(TablaDatos[[#This Row],[PacienteID]],'Datos_Ejemplo.csv'!A:A,'Datos_Ejemplo.csv'!I:I) -> 0 | N41: =ABS(TablaDatos[[#This Row],[DiasOriginal]]) -> 0 | O41: =TablaDatos[[#This Row],[FechaIngreso]]+TablaDatos[[#This Row],[DiasNuevo]] -> 45029
A42: 41 | B42: Carmen Gómez | C42: 27760 | D42: 50 | E42: F | F42: Neumonía | G42: 45166 | H42: =TablaDatos[[#This Row],[FechaIngreso]]+TablaDatos[[#This Row],[DiasNuevo]] -> 45176 | I42: 10 | J42: Privado | K42: 5801.7 | L42: =TablaDatos[[#This Row],[FechaAlta]] < TablaDatos[[#This Row],[FechaIngreso]] -> FALSE | M42: =_xlfn.XLOOKUP(TablaDatos[[#This Row],[PacienteID]],'Datos_Ejemplo.csv'!A:A,'Datos_Ejemplo.csv'!I:I) -> 10 | N42: =ABS(TablaDatos[[#This Row],[DiasOriginal]]) -> 10 | O42: =TablaDatos[[#This Row],[FechaIngreso]]+TablaDatos[[#This Row],[DiasNuevo]] -> 45176
A43: 42 | B43: Luisa Martínez | C43: 26299 | D43: 54 | E43: F | F43: Diabetes | G43: 45191 | H43: =TablaDatos[[#This Row],[FechaIngreso]]+TablaDatos[[#This Row],[DiasNuevo]] -> 45194 | I43: 3 | J43: Publico | K43: 6247.97 | L43: =TablaDatos[[#This Row],[FechaAlta]] < TablaDatos[[#This Row],[FechaIngreso]] -> FALSE | M43: =_xlfn.XLOOKUP(TablaDatos[[#This Row],[PacienteID]],'Datos_Ejemplo.csv'!A:A,'Datos_Ejemplo.csv'!I:I) -> 3 | N43: =ABS(TablaDatos[[#This Row],[DiasOriginal]]) -> 3 | O43: =TablaDatos[[#This Row],[FechaIngreso]]+TablaDatos[[#This Row],[DiasNuevo]] -> 45194
A44: 43 | B44: Laura Martínez | C44: 23012 | D44: 63 | E44: F | F44: Hipertensión | G44: 44959 | H44: =TablaDatos[[#This Row],[FechaIngreso]]+TablaDatos[[#This Row],[DiasNuevo]] -> 44994 | I44: 35 | J44: Publico | K44: 4066.39 | L44: =TablaDatos[[#This Row],[FechaAlta]] < TablaDatos[[#This Row],[FechaIngreso]] -> FALSE | M44: =_xlfn.XLOOKUP(TablaDatos[[#This Row],[PacienteID]],'Datos_Ejemplo.csv'!A:A,'Datos_Ejemplo.csv'!I:I) -> 35 | N44: =ABS(TablaDatos[[#This Row],[DiasOriginal]]) -> 35 | O44: =TablaDatos[[#This Row],[FechaIngreso]]+TablaDatos[[#This Row],[DiasNuevo]] -> 44994
A45: 44 | B45: Carlos Martínez | C45: 45292 | D45: 2 | E45: F | F45: Asma | G45: 44961 | H45: =TablaDatos[[#This Row],[FechaIngreso]]+TablaDatos[[#This Row],[DiasNuevo]] -> 44979 | I45: 18 | J45: N/A | K45: 8171.26 | L45: =TablaDatos[[#This Row],[FechaAlta]] < TablaDatos[[#This Row],[FechaIngreso]] -> FALSE | M45: =_xlfn.XLOOKUP(TablaDatos[[#This Row],[PacienteID]],'Datos_Ejemplo.csv'!A:A,'Datos_Ejemplo.csv'!I:I) -> 18 | N45: =ABS(TablaDatos[[#This Row],[DiasOriginal]]) -> 18 | O45: =TablaDatos[[#This Row],[FechaIngreso]]+TablaDatos[[#This Row],[DiasNuevo]] -> 44979
A46: 45 | B46: Jorge Gómez | C46: 27760 | D46: 50 | E46: No especificado | F46: COVID-19 | G46: 45175 | H46: =TablaDatos[[#This Row],[FechaIngreso]]+TablaDatos[[#This Row],[DiasNuevo]] -> 45191 | I46: 16 | J46: Publico | K46: 3981.47 | L46: =TablaDatos[[#This Row],[FechaAlta]] < TablaDatos[[#This Row],[FechaIngreso]] -> FALSE | M46: =_xlfn.XLOOKUP(TablaDatos[[#This Row],[PacienteID]],'Datos_Ejemplo.csv'!A:A,'Datos_Ejemplo.csv'!I:I) -> 16 | N46: =ABS(TablaDatos[[#This Row],[DiasOriginal]]) -> 16 | O46: =TablaDatos[[#This Row],[FechaIngreso]]+TablaDatos[[#This Row],[DiasNuevo]] -> 45191
A47: 46 | B47: Ana Hernández | C47: 43831 | D47: 6 | E47: M | F47: Neumonía | G47: 44976 | H47: =TablaDatos[[#This Row],[FechaIngreso]]+TablaDatos[[#This Row],[DiasNuevo]] -> 44998 | I47: 22 | J47: N/A | K47: 13930.73 | L47: =TablaDatos[[#This Row],[FechaAlta]] < TablaDatos[[#This Row],[FechaIngreso]] -> FALSE | M47: =_xlfn.XLOOKUP(TablaDatos[[#This Row],[PacienteID]],'Datos_Ejemplo.csv'!A:A,'Datos_Ejemplo.csv'!I:I) -> 22 | N47: =ABS(TablaDatos[[#This Row],[DiasOriginal]]) -> 22 | O47: =TablaDatos[[#This Row],[FechaIngreso]]+TablaDatos[[#This Row],[DiasNuevo]] -> 44998
A48: 47 | B48: Juan Morales | C48: 38717 | D48: 20 | E48: F | F48: Diabetes | G48: 45206 | H48: =TablaDatos[[#This Row],[FechaIngreso]]+TablaDatos[[#This Row],[DiasNuevo]] -> 45242 | I48: 36 | J48: Publico | K48: 2391.04 | L48: =TablaDatos[[#This Row],[FechaAlta]] < TablaDatos[[#This Row],[FechaIngreso]] -> FALSE | M48: =_xlfn.XLOOKUP(TablaDatos[[#This Row],[PacienteID]],'Datos_Ejemplo.csv'!A:A,'Datos_Ejemplo.csv'!I:I) -> 36 | N48: =ABS(TablaDatos[[#This Row],[DiasOriginal]]) -> 36 | O48: =TablaDatos[[#This Row],[FechaIngreso]]+TablaDatos[[#This Row],[DiasNuevo]] -> 45242
...
